[2023-11-22T16:06:58.076+0500] {taskinstance.py:1159} INFO - Dependencies all met for dep_context=non-requeueable deps ti=<TaskInstance: competition.get_data scheduled__2023-11-21T08:00:00+00:00 [queued]>
[2023-11-22T16:06:58.119+0500] {taskinstance.py:1159} INFO - Dependencies all met for dep_context=requeueable deps ti=<TaskInstance: competition.get_data scheduled__2023-11-21T08:00:00+00:00 [queued]>
[2023-11-22T16:06:58.120+0500] {taskinstance.py:1361} INFO - Starting attempt 1 of 2
[2023-11-22T16:06:58.187+0500] {taskinstance.py:1382} INFO - Executing <Task(BashOperator): get_data> on 2023-11-21 08:00:00+00:00
[2023-11-22T16:06:58.209+0500] {standard_task_runner.py:57} INFO - Started process 21065 to run task
[2023-11-22T16:06:58.223+0500] {standard_task_runner.py:84} INFO - Running: ['airflow', 'tasks', 'run', 'competition', 'get_data', 'scheduled__2023-11-21T08:00:00+00:00', '--job-id', '92', '--raw', '--subdir', 'DAGS_FOLDER/competition_score.py', '--cfg-path', '/tmp/tmpegp1bshh']
[2023-11-22T16:06:58.229+0500] {standard_task_runner.py:85} INFO - Job 92: Subtask get_data
[2023-11-22T16:06:58.562+0500] {task_command.py:416} INFO - Running <TaskInstance: competition.get_data scheduled__2023-11-21T08:00:00+00:00 [running]> on host Acer
[2023-11-22T16:06:59.002+0500] {taskinstance.py:1662} INFO - Exporting env vars: AIRFLOW_CTX_DAG_OWNER='makar' AIRFLOW_CTX_DAG_ID='competition' AIRFLOW_CTX_TASK_ID='get_data' AIRFLOW_CTX_EXECUTION_DATE='2023-11-21T08:00:00+00:00' AIRFLOW_CTX_TRY_NUMBER='1' AIRFLOW_CTX_DAG_RUN_ID='scheduled__2023-11-21T08:00:00+00:00'
[2023-11-22T16:06:59.010+0500] {subprocess.py:63} INFO - Tmp dir root location: /tmp
[2023-11-22T16:06:59.012+0500] {subprocess.py:75} INFO - Running command: ['/usr/bin/bash', '-c', 'python3 /home/makar/MLops_3/scripts/get_data.py']
[2023-11-22T16:06:59.049+0500] {subprocess.py:86} INFO - Output:
[2023-11-22T16:08:12.704+0500] {subprocess.py:93} INFO - Traceback (most recent call last):
[2023-11-22T16:08:12.706+0500] {subprocess.py:93} INFO -   File "/home/makar/.local/lib/python3.10/site-packages/urllib3/connection.py", line 203, in _new_conn
[2023-11-22T16:08:12.707+0500] {subprocess.py:93} INFO -     sock = connection.create_connection(
[2023-11-22T16:08:12.708+0500] {subprocess.py:93} INFO -   File "/home/makar/.local/lib/python3.10/site-packages/urllib3/util/connection.py", line 85, in create_connection
[2023-11-22T16:08:12.709+0500] {subprocess.py:93} INFO -     raise err
[2023-11-22T16:08:12.710+0500] {subprocess.py:93} INFO -   File "/home/makar/.local/lib/python3.10/site-packages/urllib3/util/connection.py", line 73, in create_connection
[2023-11-22T16:08:12.711+0500] {subprocess.py:93} INFO -     sock.connect(sa)
[2023-11-22T16:08:12.712+0500] {subprocess.py:93} INFO - ConnectionRefusedError: [Errno 111] Connection refused
[2023-11-22T16:08:12.713+0500] {subprocess.py:93} INFO - 
[2023-11-22T16:08:12.714+0500] {subprocess.py:93} INFO - The above exception was the direct cause of the following exception:
[2023-11-22T16:08:12.714+0500] {subprocess.py:93} INFO - 
[2023-11-22T16:08:12.715+0500] {subprocess.py:93} INFO - Traceback (most recent call last):
[2023-11-22T16:08:12.716+0500] {subprocess.py:93} INFO -   File "/home/makar/.local/lib/python3.10/site-packages/urllib3/connectionpool.py", line 790, in urlopen
[2023-11-22T16:08:12.716+0500] {subprocess.py:93} INFO -     response = self._make_request(
[2023-11-22T16:08:12.717+0500] {subprocess.py:93} INFO -   File "/home/makar/.local/lib/python3.10/site-packages/urllib3/connectionpool.py", line 496, in _make_request
[2023-11-22T16:08:12.718+0500] {subprocess.py:93} INFO -     conn.request(
[2023-11-22T16:08:12.719+0500] {subprocess.py:93} INFO -   File "/home/makar/.local/lib/python3.10/site-packages/urllib3/connection.py", line 395, in request
[2023-11-22T16:08:12.719+0500] {subprocess.py:93} INFO -     self.endheaders()
[2023-11-22T16:08:12.720+0500] {subprocess.py:93} INFO -   File "/usr/lib/python3.10/http/client.py", line 1278, in endheaders
[2023-11-22T16:08:12.721+0500] {subprocess.py:93} INFO -     self._send_output(message_body, encode_chunked=encode_chunked)
[2023-11-22T16:08:12.721+0500] {subprocess.py:93} INFO -   File "/usr/lib/python3.10/http/client.py", line 1038, in _send_output
[2023-11-22T16:08:12.722+0500] {subprocess.py:93} INFO -     self.send(msg)
[2023-11-22T16:08:12.723+0500] {subprocess.py:93} INFO -   File "/usr/lib/python3.10/http/client.py", line 976, in send
[2023-11-22T16:08:12.724+0500] {subprocess.py:93} INFO -     self.connect()
[2023-11-22T16:08:12.724+0500] {subprocess.py:93} INFO -   File "/home/makar/.local/lib/python3.10/site-packages/urllib3/connection.py", line 243, in connect
[2023-11-22T16:08:12.725+0500] {subprocess.py:93} INFO -     self.sock = self._new_conn()
[2023-11-22T16:08:12.725+0500] {subprocess.py:93} INFO -   File "/home/makar/.local/lib/python3.10/site-packages/urllib3/connection.py", line 218, in _new_conn
[2023-11-22T16:08:12.726+0500] {subprocess.py:93} INFO -     raise NewConnectionError(
[2023-11-22T16:08:12.727+0500] {subprocess.py:93} INFO - urllib3.exceptions.NewConnectionError: <urllib3.connection.HTTPConnection object at 0x7fa58e37c940>: Failed to establish a new connection: [Errno 111] Connection refused
[2023-11-22T16:08:12.728+0500] {subprocess.py:93} INFO - 
[2023-11-22T16:08:12.730+0500] {subprocess.py:93} INFO - The above exception was the direct cause of the following exception:
[2023-11-22T16:08:12.731+0500] {subprocess.py:93} INFO - 
[2023-11-22T16:08:12.732+0500] {subprocess.py:93} INFO - Traceback (most recent call last):
[2023-11-22T16:08:12.732+0500] {subprocess.py:93} INFO -   File "/usr/local/lib/python3.10/dist-packages/requests/adapters.py", line 486, in send
[2023-11-22T16:08:12.733+0500] {subprocess.py:93} INFO -     resp = conn.urlopen(
[2023-11-22T16:08:12.733+0500] {subprocess.py:93} INFO -   File "/home/makar/.local/lib/python3.10/site-packages/urllib3/connectionpool.py", line 874, in urlopen
[2023-11-22T16:08:12.734+0500] {subprocess.py:93} INFO -     return self.urlopen(
[2023-11-22T16:08:12.735+0500] {subprocess.py:93} INFO -   File "/home/makar/.local/lib/python3.10/site-packages/urllib3/connectionpool.py", line 874, in urlopen
[2023-11-22T16:08:12.735+0500] {subprocess.py:93} INFO -     return self.urlopen(
[2023-11-22T16:08:12.736+0500] {subprocess.py:93} INFO -   File "/home/makar/.local/lib/python3.10/site-packages/urllib3/connectionpool.py", line 874, in urlopen
[2023-11-22T16:08:12.737+0500] {subprocess.py:93} INFO -     return self.urlopen(
[2023-11-22T16:08:12.737+0500] {subprocess.py:93} INFO -   [Previous line repeated 2 more times]
[2023-11-22T16:08:12.738+0500] {subprocess.py:93} INFO -   File "/home/makar/.local/lib/python3.10/site-packages/urllib3/connectionpool.py", line 844, in urlopen
[2023-11-22T16:08:12.739+0500] {subprocess.py:93} INFO -     retries = retries.increment(
[2023-11-22T16:08:12.739+0500] {subprocess.py:93} INFO -   File "/home/makar/.local/lib/python3.10/site-packages/urllib3/util/retry.py", line 515, in increment
[2023-11-22T16:08:12.740+0500] {subprocess.py:93} INFO -     raise MaxRetryError(_pool, url, reason) from reason  # type: ignore[arg-type]
[2023-11-22T16:08:12.740+0500] {subprocess.py:93} INFO - urllib3.exceptions.MaxRetryError: HTTPConnectionPool(host='localhost', port=5000): Max retries exceeded with url: /api/2.0/mlflow/experiments/get-by-name?experiment_name=get_data (Caused by NewConnectionError('<urllib3.connection.HTTPConnection object at 0x7fa58e37c940>: Failed to establish a new connection: [Errno 111] Connection refused'))
[2023-11-22T16:08:12.741+0500] {subprocess.py:93} INFO - 
[2023-11-22T16:08:12.742+0500] {subprocess.py:93} INFO - During handling of the above exception, another exception occurred:
[2023-11-22T16:08:12.742+0500] {subprocess.py:93} INFO - 
[2023-11-22T16:08:12.743+0500] {subprocess.py:93} INFO - Traceback (most recent call last):
[2023-11-22T16:08:12.744+0500] {subprocess.py:93} INFO -   File "/home/makar/.local/lib/python3.10/site-packages/mlflow/utils/rest_utils.py", line 99, in http_request
[2023-11-22T16:08:12.745+0500] {subprocess.py:93} INFO -     return _get_http_response_with_retries(
[2023-11-22T16:08:12.746+0500] {subprocess.py:93} INFO -   File "/home/makar/.local/lib/python3.10/site-packages/mlflow/utils/request_utils.py", line 151, in _get_http_response_with_retries
[2023-11-22T16:08:12.746+0500] {subprocess.py:93} INFO -     return session.request(method, url, **kwargs)
[2023-11-22T16:08:12.747+0500] {subprocess.py:93} INFO -   File "/usr/local/lib/python3.10/dist-packages/requests/sessions.py", line 589, in request
[2023-11-22T16:08:12.748+0500] {subprocess.py:93} INFO -     resp = self.send(prep, **send_kwargs)
[2023-11-22T16:08:12.748+0500] {subprocess.py:93} INFO -   File "/usr/local/lib/python3.10/dist-packages/requests/sessions.py", line 703, in send
[2023-11-22T16:08:12.749+0500] {subprocess.py:93} INFO -     r = adapter.send(request, **kwargs)
[2023-11-22T16:08:12.749+0500] {subprocess.py:93} INFO -   File "/usr/local/lib/python3.10/dist-packages/requests/adapters.py", line 519, in send
[2023-11-22T16:08:12.750+0500] {subprocess.py:93} INFO -     raise ConnectionError(e, request=request)
[2023-11-22T16:08:12.751+0500] {subprocess.py:93} INFO - requests.exceptions.ConnectionError: HTTPConnectionPool(host='localhost', port=5000): Max retries exceeded with url: /api/2.0/mlflow/experiments/get-by-name?experiment_name=get_data (Caused by NewConnectionError('<urllib3.connection.HTTPConnection object at 0x7fa58e37c940>: Failed to establish a new connection: [Errno 111] Connection refused'))
[2023-11-22T16:08:12.751+0500] {subprocess.py:93} INFO - 
[2023-11-22T16:08:12.752+0500] {subprocess.py:93} INFO - During handling of the above exception, another exception occurred:
[2023-11-22T16:08:12.753+0500] {subprocess.py:93} INFO - 
[2023-11-22T16:08:12.753+0500] {subprocess.py:93} INFO - Traceback (most recent call last):
[2023-11-22T16:08:12.754+0500] {subprocess.py:93} INFO -   File "/home/makar/MLops_3/scripts/get_data.py", line 8, in <module>
[2023-11-22T16:08:12.754+0500] {subprocess.py:93} INFO -     mlflow.set_experiment("get_data")
[2023-11-22T16:08:12.755+0500] {subprocess.py:93} INFO -   File "/home/makar/.local/lib/python3.10/site-packages/mlflow/tracking/fluent.py", line 135, in set_experiment
[2023-11-22T16:08:12.756+0500] {subprocess.py:93} INFO -     experiment = client.get_experiment_by_name(experiment_name)
[2023-11-22T16:08:12.756+0500] {subprocess.py:93} INFO -   File "/home/makar/.local/lib/python3.10/site-packages/mlflow/tracking/client.py", line 513, in get_experiment_by_name
[2023-11-22T16:08:12.757+0500] {subprocess.py:93} INFO -     return self._tracking_client.get_experiment_by_name(name)
[2023-11-22T16:08:12.757+0500] {subprocess.py:93} INFO -   File "/home/makar/.local/lib/python3.10/site-packages/mlflow/tracking/_tracking_service/client.py", line 221, in get_experiment_by_name
[2023-11-22T16:08:12.758+0500] {subprocess.py:93} INFO -     return self.store.get_experiment_by_name(name)
[2023-11-22T16:08:12.759+0500] {subprocess.py:93} INFO -   File "/home/makar/.local/lib/python3.10/site-packages/mlflow/store/tracking/rest_store.py", line 306, in get_experiment_by_name
[2023-11-22T16:08:12.760+0500] {subprocess.py:93} INFO -     response_proto = self._call_endpoint(GetExperimentByName, req_body)
[2023-11-22T16:08:12.761+0500] {subprocess.py:93} INFO -   File "/home/makar/.local/lib/python3.10/site-packages/mlflow/store/tracking/rest_store.py", line 59, in _call_endpoint
[2023-11-22T16:08:12.761+0500] {subprocess.py:93} INFO -     return call_endpoint(self.get_host_creds(), endpoint, method, json_body, response_proto)
[2023-11-22T16:08:12.762+0500] {subprocess.py:93} INFO -   File "/home/makar/.local/lib/python3.10/site-packages/mlflow/utils/rest_utils.py", line 206, in call_endpoint
[2023-11-22T16:08:12.763+0500] {subprocess.py:93} INFO -     response = http_request(**call_kwargs)
[2023-11-22T16:08:12.763+0500] {subprocess.py:93} INFO -   File "/home/makar/.local/lib/python3.10/site-packages/mlflow/utils/rest_utils.py", line 120, in http_request
[2023-11-22T16:08:12.764+0500] {subprocess.py:93} INFO -     raise MlflowException(f"API request to {url} failed with exception {e}")
[2023-11-22T16:08:12.765+0500] {subprocess.py:93} INFO - mlflow.exceptions.MlflowException: API request to http://localhost:5000/api/2.0/mlflow/experiments/get-by-name failed with exception HTTPConnectionPool(host='localhost', port=5000): Max retries exceeded with url: /api/2.0/mlflow/experiments/get-by-name?experiment_name=get_data (Caused by NewConnectionError('<urllib3.connection.HTTPConnection object at 0x7fa58e37c940>: Failed to establish a new connection: [Errno 111] Connection refused'))
[2023-11-22T16:08:13.280+0500] {subprocess.py:97} INFO - Command exited with return code 1
[2023-11-22T16:08:13.341+0500] {taskinstance.py:1937} ERROR - Task failed with exception
Traceback (most recent call last):
  File "/usr/local/lib/python3.10/dist-packages/airflow/operators/bash.py", line 210, in execute
    raise AirflowException(
airflow.exceptions.AirflowException: Bash command failed. The command returned a non-zero exit code 1.
[2023-11-22T16:08:13.353+0500] {taskinstance.py:1400} INFO - Marking task as UP_FOR_RETRY. dag_id=competition, task_id=get_data, execution_date=20231121T080000, start_date=20231122T110658, end_date=20231122T110813
[2023-11-22T16:08:13.402+0500] {standard_task_runner.py:104} ERROR - Failed to execute job 92 for task get_data (Bash command failed. The command returned a non-zero exit code 1.; 21065)
[2023-11-22T16:08:13.445+0500] {local_task_job_runner.py:228} INFO - Task exited with return code 1
[2023-11-22T16:08:13.547+0500] {taskinstance.py:2778} INFO - 0 downstream tasks scheduled from follow-on schedule check
