[2023-11-21T18:45:41.870+0500] {taskinstance.py:1159} INFO - Dependencies all met for dep_context=non-requeueable deps ti=<TaskInstance: competition.train_model manual__2023-11-21T13:41:10.007320+00:00 [queued]>
[2023-11-21T18:45:41.909+0500] {taskinstance.py:1159} INFO - Dependencies all met for dep_context=requeueable deps ti=<TaskInstance: competition.train_model manual__2023-11-21T13:41:10.007320+00:00 [queued]>
[2023-11-21T18:45:41.910+0500] {taskinstance.py:1361} INFO - Starting attempt 1 of 2
[2023-11-21T18:45:41.971+0500] {taskinstance.py:1382} INFO - Executing <Task(BashOperator): train_model> on 2023-11-21 13:41:10.007320+00:00
[2023-11-21T18:45:41.993+0500] {standard_task_runner.py:57} INFO - Started process 38047 to run task
[2023-11-21T18:45:42.004+0500] {standard_task_runner.py:84} INFO - Running: ['airflow', 'tasks', 'run', 'competition', 'train_model', 'manual__2023-11-21T13:41:10.007320+00:00', '--job-id', '46', '--raw', '--subdir', 'DAGS_FOLDER/competition_score.py', '--cfg-path', '/tmp/tmps0xysxkb']
[2023-11-21T18:45:42.010+0500] {standard_task_runner.py:85} INFO - Job 46: Subtask train_model
[2023-11-21T18:45:42.249+0500] {task_command.py:416} INFO - Running <TaskInstance: competition.train_model manual__2023-11-21T13:41:10.007320+00:00 [running]> on host Acer
[2023-11-21T18:45:42.639+0500] {taskinstance.py:1662} INFO - Exporting env vars: AIRFLOW_CTX_DAG_OWNER='makar' AIRFLOW_CTX_DAG_ID='competition' AIRFLOW_CTX_TASK_ID='train_model' AIRFLOW_CTX_EXECUTION_DATE='2023-11-21T13:41:10.007320+00:00' AIRFLOW_CTX_TRY_NUMBER='1' AIRFLOW_CTX_DAG_RUN_ID='manual__2023-11-21T13:41:10.007320+00:00'
[2023-11-21T18:45:42.646+0500] {subprocess.py:63} INFO - Tmp dir root location: /tmp
[2023-11-21T18:45:42.649+0500] {subprocess.py:75} INFO - Running command: ['/usr/bin/bash', '-c', 'python3 /home/makar/MLops_3/scripts/train_model.py']
[2023-11-21T18:45:42.686+0500] {subprocess.py:86} INFO - Output:
[2023-11-21T18:47:49.010+0500] {job.py:219} ERROR - Job heartbeat got an exception
Traceback (most recent call last):
  File "/usr/local/lib/python3.10/dist-packages/sqlalchemy/engine/base.py", line 3371, in _wrap_pool_connect
    return fn()
  File "/usr/local/lib/python3.10/dist-packages/sqlalchemy/pool/base.py", line 327, in connect
    return _ConnectionFairy._checkout(self)
  File "/usr/local/lib/python3.10/dist-packages/sqlalchemy/pool/base.py", line 894, in _checkout
    fairy = _ConnectionRecord.checkout(pool)
  File "/usr/local/lib/python3.10/dist-packages/sqlalchemy/pool/base.py", line 493, in checkout
    rec = pool._do_get()
  File "/usr/local/lib/python3.10/dist-packages/sqlalchemy/pool/impl.py", line 256, in _do_get
    return self._create_connection()
  File "/usr/local/lib/python3.10/dist-packages/sqlalchemy/pool/base.py", line 273, in _create_connection
    return _ConnectionRecord(self)
  File "/usr/local/lib/python3.10/dist-packages/sqlalchemy/pool/base.py", line 388, in __init__
    self.__connect()
  File "/usr/local/lib/python3.10/dist-packages/sqlalchemy/pool/base.py", line 690, in __connect
    with util.safe_reraise():
  File "/usr/local/lib/python3.10/dist-packages/sqlalchemy/util/langhelpers.py", line 70, in __exit__
    compat.raise_(
  File "/usr/local/lib/python3.10/dist-packages/sqlalchemy/util/compat.py", line 211, in raise_
    raise exception
  File "/usr/local/lib/python3.10/dist-packages/sqlalchemy/pool/base.py", line 686, in __connect
    self.dbapi_connection = connection = pool._invoke_creator(self)
  File "/usr/local/lib/python3.10/dist-packages/sqlalchemy/engine/create.py", line 574, in connect
    return dialect.connect(*cargs, **cparams)
  File "/usr/local/lib/python3.10/dist-packages/sqlalchemy/engine/default.py", line 598, in connect
    return self.dbapi.connect(*cargs, **cparams)
  File "/home/makar/.local/lib/python3.10/site-packages/psycopg2/__init__.py", line 122, in connect
    conn = _connect(dsn, connection_factory=connection_factory, **kwasync)
psycopg2.OperationalError: connection to server at "localhost" (127.0.0.1), port 5432 failed: SSL SYSCALL error: EOF detected


The above exception was the direct cause of the following exception:

Traceback (most recent call last):
  File "/usr/local/lib/python3.10/dist-packages/airflow/jobs/job.py", line 190, in heartbeat
    session.merge(self)
  File "/usr/local/lib/python3.10/dist-packages/sqlalchemy/orm/session.py", line 3056, in merge
    return self._merge(
  File "/usr/local/lib/python3.10/dist-packages/sqlalchemy/orm/session.py", line 3136, in _merge
    merged = self.get(
  File "/usr/local/lib/python3.10/dist-packages/sqlalchemy/orm/session.py", line 2853, in get
    return self._get_impl(
  File "/usr/local/lib/python3.10/dist-packages/sqlalchemy/orm/session.py", line 2975, in _get_impl
    return db_load_fn(
  File "/usr/local/lib/python3.10/dist-packages/sqlalchemy/orm/loading.py", line 530, in load_on_pk_identity
    session.execute(
  File "/usr/local/lib/python3.10/dist-packages/sqlalchemy/orm/session.py", line 1716, in execute
    conn = self._connection_for_bind(bind)
  File "/usr/local/lib/python3.10/dist-packages/sqlalchemy/orm/session.py", line 1555, in _connection_for_bind
    return self._transaction._connection_for_bind(
  File "/usr/local/lib/python3.10/dist-packages/sqlalchemy/orm/session.py", line 750, in _connection_for_bind
    conn = bind.connect()
  File "/usr/local/lib/python3.10/dist-packages/sqlalchemy/future/engine.py", line 406, in connect
    return super(Engine, self).connect()
  File "/usr/local/lib/python3.10/dist-packages/sqlalchemy/engine/base.py", line 3325, in connect
    return self._connection_cls(self, close_with_result=close_with_result)
  File "/usr/local/lib/python3.10/dist-packages/sqlalchemy/engine/base.py", line 96, in __init__
    else engine.raw_connection()
  File "/usr/local/lib/python3.10/dist-packages/sqlalchemy/engine/base.py", line 3404, in raw_connection
    return self._wrap_pool_connect(self.pool.connect, _connection)
  File "/usr/local/lib/python3.10/dist-packages/sqlalchemy/engine/base.py", line 3374, in _wrap_pool_connect
    Connection._handle_dbapi_exception_noconnection(
  File "/usr/local/lib/python3.10/dist-packages/sqlalchemy/engine/base.py", line 2208, in _handle_dbapi_exception_noconnection
    util.raise_(
  File "/usr/local/lib/python3.10/dist-packages/sqlalchemy/util/compat.py", line 211, in raise_
    raise exception
  File "/usr/local/lib/python3.10/dist-packages/sqlalchemy/engine/base.py", line 3371, in _wrap_pool_connect
    return fn()
  File "/usr/local/lib/python3.10/dist-packages/sqlalchemy/pool/base.py", line 327, in connect
    return _ConnectionFairy._checkout(self)
  File "/usr/local/lib/python3.10/dist-packages/sqlalchemy/pool/base.py", line 894, in _checkout
    fairy = _ConnectionRecord.checkout(pool)
  File "/usr/local/lib/python3.10/dist-packages/sqlalchemy/pool/base.py", line 493, in checkout
    rec = pool._do_get()
  File "/usr/local/lib/python3.10/dist-packages/sqlalchemy/pool/impl.py", line 256, in _do_get
    return self._create_connection()
  File "/usr/local/lib/python3.10/dist-packages/sqlalchemy/pool/base.py", line 273, in _create_connection
    return _ConnectionRecord(self)
  File "/usr/local/lib/python3.10/dist-packages/sqlalchemy/pool/base.py", line 388, in __init__
    self.__connect()
  File "/usr/local/lib/python3.10/dist-packages/sqlalchemy/pool/base.py", line 690, in __connect
    with util.safe_reraise():
  File "/usr/local/lib/python3.10/dist-packages/sqlalchemy/util/langhelpers.py", line 70, in __exit__
    compat.raise_(
  File "/usr/local/lib/python3.10/dist-packages/sqlalchemy/util/compat.py", line 211, in raise_
    raise exception
  File "/usr/local/lib/python3.10/dist-packages/sqlalchemy/pool/base.py", line 686, in __connect
    self.dbapi_connection = connection = pool._invoke_creator(self)
  File "/usr/local/lib/python3.10/dist-packages/sqlalchemy/engine/create.py", line 574, in connect
    return dialect.connect(*cargs, **cparams)
  File "/usr/local/lib/python3.10/dist-packages/sqlalchemy/engine/default.py", line 598, in connect
    return self.dbapi.connect(*cargs, **cparams)
  File "/home/makar/.local/lib/python3.10/site-packages/psycopg2/__init__.py", line 122, in connect
    conn = _connect(dsn, connection_factory=connection_factory, **kwasync)
sqlalchemy.exc.OperationalError: (psycopg2.OperationalError) connection to server at "localhost" (127.0.0.1), port 5432 failed: SSL SYSCALL error: EOF detected

(Background on this error at: https://sqlalche.me/e/14/e3q8)
[2023-11-21T18:48:04.817+0500] {subprocess.py:93} INFO - 2023/11/21 18:48:04 WARNING mlflow.utils.environment: Encountered an unexpected error while inferring pip requirements (model URI: /tmp/tmppp2tdj7f/model/model.pkl, flavor: sklearn), fall back to return ['scikit-learn==1.2.2', 'cloudpickle==2.2.1']. Set logging level to DEBUG to see the full traceback.
[2023-11-21T18:48:06.034+0500] {subprocess.py:93} INFO - /home/makar/.local/lib/python3.10/site-packages/_distutils_hack/__init__.py:33: UserWarning: Setuptools is replacing distutils.
[2023-11-21T18:48:06.119+0500] {subprocess.py:93} INFO -   warnings.warn("Setuptools is replacing distutils.")
[2023-11-21T18:48:15.782+0500] {subprocess.py:93} INFO - Registered model 'rf_regressor' already exists. Creating a new version of this model...
[2023-11-21T18:48:17.367+0500] {subprocess.py:93} INFO - Created version '3' of model 'rf_regressor'.
[2023-11-21T18:48:18.622+0500] {subprocess.py:93} INFO - /home/makar/MLops_3/scripts/train_model.py:29: DataConversionWarning: A column-vector y was passed when a 1d array was expected. Please change the shape of y to (n_samples,), for example using ravel().
[2023-11-21T18:48:18.625+0500] {subprocess.py:93} INFO -   rf_regressor.fit(X_train, y_train)
[2023-11-21T18:50:58.791+0500] {subprocess.py:97} INFO - Command exited with return code 0
[2023-11-21T18:50:59.053+0500] {taskinstance.py:1400} INFO - Marking task as SUCCESS. dag_id=competition, task_id=train_model, execution_date=20231121T134110, start_date=20231121T134541, end_date=20231121T135059
[2023-11-21T18:50:59.206+0500] {local_task_job_runner.py:228} INFO - Task exited with return code 0
[2023-11-21T18:50:59.484+0500] {taskinstance.py:2778} INFO - 1 downstream tasks scheduled from follow-on schedule check
