[2023-11-22T15:27:18.689+0500] {taskinstance.py:1159} INFO - Dependencies all met for dep_context=non-requeueable deps ti=<TaskInstance: competition.get_data scheduled__2023-11-21T00:00:00+00:00 [queued]>
[2023-11-22T15:27:18.725+0500] {taskinstance.py:1159} INFO - Dependencies all met for dep_context=requeueable deps ti=<TaskInstance: competition.get_data scheduled__2023-11-21T00:00:00+00:00 [queued]>
[2023-11-22T15:27:18.726+0500] {taskinstance.py:1361} INFO - Starting attempt 1 of 2
[2023-11-22T15:27:18.778+0500] {taskinstance.py:1382} INFO - Executing <Task(BashOperator): get_data> on 2023-11-21 00:00:00+00:00
[2023-11-22T15:27:18.792+0500] {standard_task_runner.py:57} INFO - Started process 9994 to run task
[2023-11-22T15:27:18.801+0500] {standard_task_runner.py:84} INFO - Running: ['airflow', 'tasks', 'run', 'competition', 'get_data', 'scheduled__2023-11-21T00:00:00+00:00', '--job-id', '49', '--raw', '--subdir', 'DAGS_FOLDER/competition_score.py', '--cfg-path', '/tmp/tmp4uh875qz']
[2023-11-22T15:27:18.806+0500] {standard_task_runner.py:85} INFO - Job 49: Subtask get_data
[2023-11-22T15:27:19.032+0500] {task_command.py:416} INFO - Running <TaskInstance: competition.get_data scheduled__2023-11-21T00:00:00+00:00 [running]> on host Acer
[2023-11-22T15:27:19.383+0500] {taskinstance.py:1662} INFO - Exporting env vars: AIRFLOW_CTX_DAG_OWNER='makar' AIRFLOW_CTX_DAG_ID='competition' AIRFLOW_CTX_TASK_ID='get_data' AIRFLOW_CTX_EXECUTION_DATE='2023-11-21T00:00:00+00:00' AIRFLOW_CTX_TRY_NUMBER='1' AIRFLOW_CTX_DAG_RUN_ID='scheduled__2023-11-21T00:00:00+00:00'
[2023-11-22T15:27:19.388+0500] {subprocess.py:63} INFO - Tmp dir root location: /tmp
[2023-11-22T15:27:19.390+0500] {subprocess.py:75} INFO - Running command: ['/usr/bin/bash', '-c', 'python3 /home/makar/MLops_3/scripts/get_data.py']
[2023-11-22T15:27:19.422+0500] {subprocess.py:86} INFO - Output:
[2023-11-22T15:28:26.276+0500] {subprocess.py:93} INFO - Traceback (most recent call last):
[2023-11-22T15:28:26.277+0500] {subprocess.py:93} INFO -   File "/home/makar/.local/lib/python3.10/site-packages/urllib3/connection.py", line 203, in _new_conn
[2023-11-22T15:28:26.278+0500] {subprocess.py:93} INFO -     sock = connection.create_connection(
[2023-11-22T15:28:26.279+0500] {subprocess.py:93} INFO -   File "/home/makar/.local/lib/python3.10/site-packages/urllib3/util/connection.py", line 85, in create_connection
[2023-11-22T15:28:26.279+0500] {subprocess.py:93} INFO -     raise err
[2023-11-22T15:28:26.280+0500] {subprocess.py:93} INFO -   File "/home/makar/.local/lib/python3.10/site-packages/urllib3/util/connection.py", line 73, in create_connection
[2023-11-22T15:28:26.281+0500] {subprocess.py:93} INFO -     sock.connect(sa)
[2023-11-22T15:28:26.282+0500] {subprocess.py:93} INFO - ConnectionRefusedError: [Errno 111] Connection refused
[2023-11-22T15:28:26.283+0500] {subprocess.py:93} INFO - 
[2023-11-22T15:28:26.283+0500] {subprocess.py:93} INFO - The above exception was the direct cause of the following exception:
[2023-11-22T15:28:26.284+0500] {subprocess.py:93} INFO - 
[2023-11-22T15:28:26.285+0500] {subprocess.py:93} INFO - Traceback (most recent call last):
[2023-11-22T15:28:26.286+0500] {subprocess.py:93} INFO -   File "/home/makar/.local/lib/python3.10/site-packages/urllib3/connectionpool.py", line 790, in urlopen
[2023-11-22T15:28:26.287+0500] {subprocess.py:93} INFO -     response = self._make_request(
[2023-11-22T15:28:26.288+0500] {subprocess.py:93} INFO -   File "/home/makar/.local/lib/python3.10/site-packages/urllib3/connectionpool.py", line 496, in _make_request
[2023-11-22T15:28:26.289+0500] {subprocess.py:93} INFO -     conn.request(
[2023-11-22T15:28:26.290+0500] {subprocess.py:93} INFO -   File "/home/makar/.local/lib/python3.10/site-packages/urllib3/connection.py", line 395, in request
[2023-11-22T15:28:26.290+0500] {subprocess.py:93} INFO -     self.endheaders()
[2023-11-22T15:28:26.291+0500] {subprocess.py:93} INFO -   File "/usr/lib/python3.10/http/client.py", line 1278, in endheaders
[2023-11-22T15:28:26.292+0500] {subprocess.py:93} INFO -     self._send_output(message_body, encode_chunked=encode_chunked)
[2023-11-22T15:28:26.293+0500] {subprocess.py:93} INFO -   File "/usr/lib/python3.10/http/client.py", line 1038, in _send_output
[2023-11-22T15:28:26.294+0500] {subprocess.py:93} INFO -     self.send(msg)
[2023-11-22T15:28:26.295+0500] {subprocess.py:93} INFO -   File "/usr/lib/python3.10/http/client.py", line 976, in send
[2023-11-22T15:28:26.295+0500] {subprocess.py:93} INFO -     self.connect()
[2023-11-22T15:28:26.296+0500] {subprocess.py:93} INFO -   File "/home/makar/.local/lib/python3.10/site-packages/urllib3/connection.py", line 243, in connect
[2023-11-22T15:28:26.297+0500] {subprocess.py:93} INFO -     self.sock = self._new_conn()
[2023-11-22T15:28:26.298+0500] {subprocess.py:93} INFO -   File "/home/makar/.local/lib/python3.10/site-packages/urllib3/connection.py", line 218, in _new_conn
[2023-11-22T15:28:26.298+0500] {subprocess.py:93} INFO -     raise NewConnectionError(
[2023-11-22T15:28:26.299+0500] {subprocess.py:93} INFO - urllib3.exceptions.NewConnectionError: <urllib3.connection.HTTPConnection object at 0x7f9912234940>: Failed to establish a new connection: [Errno 111] Connection refused
[2023-11-22T15:28:26.300+0500] {subprocess.py:93} INFO - 
[2023-11-22T15:28:26.301+0500] {subprocess.py:93} INFO - The above exception was the direct cause of the following exception:
[2023-11-22T15:28:26.302+0500] {subprocess.py:93} INFO - 
[2023-11-22T15:28:26.303+0500] {subprocess.py:93} INFO - Traceback (most recent call last):
[2023-11-22T15:28:26.304+0500] {subprocess.py:93} INFO -   File "/usr/local/lib/python3.10/dist-packages/requests/adapters.py", line 486, in send
[2023-11-22T15:28:26.305+0500] {subprocess.py:93} INFO -     resp = conn.urlopen(
[2023-11-22T15:28:26.306+0500] {subprocess.py:93} INFO -   File "/home/makar/.local/lib/python3.10/site-packages/urllib3/connectionpool.py", line 874, in urlopen
[2023-11-22T15:28:26.307+0500] {subprocess.py:93} INFO -     return self.urlopen(
[2023-11-22T15:28:26.308+0500] {subprocess.py:93} INFO -   File "/home/makar/.local/lib/python3.10/site-packages/urllib3/connectionpool.py", line 874, in urlopen
[2023-11-22T15:28:26.309+0500] {subprocess.py:93} INFO -     return self.urlopen(
[2023-11-22T15:28:26.310+0500] {subprocess.py:93} INFO -   File "/home/makar/.local/lib/python3.10/site-packages/urllib3/connectionpool.py", line 874, in urlopen
[2023-11-22T15:28:26.311+0500] {subprocess.py:93} INFO -     return self.urlopen(
[2023-11-22T15:28:26.312+0500] {subprocess.py:93} INFO -   [Previous line repeated 2 more times]
[2023-11-22T15:28:26.313+0500] {subprocess.py:93} INFO -   File "/home/makar/.local/lib/python3.10/site-packages/urllib3/connectionpool.py", line 844, in urlopen
[2023-11-22T15:28:26.314+0500] {subprocess.py:93} INFO -     retries = retries.increment(
[2023-11-22T15:28:26.315+0500] {subprocess.py:93} INFO -   File "/home/makar/.local/lib/python3.10/site-packages/urllib3/util/retry.py", line 515, in increment
[2023-11-22T15:28:26.316+0500] {subprocess.py:93} INFO -     raise MaxRetryError(_pool, url, reason) from reason  # type: ignore[arg-type]
[2023-11-22T15:28:26.317+0500] {subprocess.py:93} INFO - urllib3.exceptions.MaxRetryError: HTTPConnectionPool(host='localhost', port=5000): Max retries exceeded with url: /api/2.0/mlflow/experiments/get-by-name?experiment_name=get_data (Caused by NewConnectionError('<urllib3.connection.HTTPConnection object at 0x7f9912234940>: Failed to establish a new connection: [Errno 111] Connection refused'))
[2023-11-22T15:28:26.318+0500] {subprocess.py:93} INFO - 
[2023-11-22T15:28:26.319+0500] {subprocess.py:93} INFO - During handling of the above exception, another exception occurred:
[2023-11-22T15:28:26.320+0500] {subprocess.py:93} INFO - 
[2023-11-22T15:28:26.321+0500] {subprocess.py:93} INFO - Traceback (most recent call last):
[2023-11-22T15:28:26.322+0500] {subprocess.py:93} INFO -   File "/home/makar/.local/lib/python3.10/site-packages/mlflow/utils/rest_utils.py", line 99, in http_request
[2023-11-22T15:28:26.323+0500] {subprocess.py:93} INFO -     return _get_http_response_with_retries(
[2023-11-22T15:28:26.324+0500] {subprocess.py:93} INFO -   File "/home/makar/.local/lib/python3.10/site-packages/mlflow/utils/request_utils.py", line 151, in _get_http_response_with_retries
[2023-11-22T15:28:26.325+0500] {subprocess.py:93} INFO -     return session.request(method, url, **kwargs)
[2023-11-22T15:28:26.326+0500] {subprocess.py:93} INFO -   File "/usr/local/lib/python3.10/dist-packages/requests/sessions.py", line 589, in request
[2023-11-22T15:28:26.327+0500] {subprocess.py:93} INFO -     resp = self.send(prep, **send_kwargs)
[2023-11-22T15:28:26.328+0500] {subprocess.py:93} INFO -   File "/usr/local/lib/python3.10/dist-packages/requests/sessions.py", line 703, in send
[2023-11-22T15:28:26.329+0500] {subprocess.py:93} INFO -     r = adapter.send(request, **kwargs)
[2023-11-22T15:28:26.330+0500] {subprocess.py:93} INFO -   File "/usr/local/lib/python3.10/dist-packages/requests/adapters.py", line 519, in send
[2023-11-22T15:28:26.331+0500] {subprocess.py:93} INFO -     raise ConnectionError(e, request=request)
[2023-11-22T15:28:26.332+0500] {subprocess.py:93} INFO - requests.exceptions.ConnectionError: HTTPConnectionPool(host='localhost', port=5000): Max retries exceeded with url: /api/2.0/mlflow/experiments/get-by-name?experiment_name=get_data (Caused by NewConnectionError('<urllib3.connection.HTTPConnection object at 0x7f9912234940>: Failed to establish a new connection: [Errno 111] Connection refused'))
[2023-11-22T15:28:26.333+0500] {subprocess.py:93} INFO - 
[2023-11-22T15:28:26.334+0500] {subprocess.py:93} INFO - During handling of the above exception, another exception occurred:
[2023-11-22T15:28:26.335+0500] {subprocess.py:93} INFO - 
[2023-11-22T15:28:26.336+0500] {subprocess.py:93} INFO - Traceback (most recent call last):
[2023-11-22T15:28:26.337+0500] {subprocess.py:93} INFO -   File "/home/makar/MLops_3/scripts/get_data.py", line 8, in <module>
[2023-11-22T15:28:26.338+0500] {subprocess.py:93} INFO -     mlflow.set_experiment("get_data")
[2023-11-22T15:28:26.339+0500] {subprocess.py:93} INFO -   File "/home/makar/.local/lib/python3.10/site-packages/mlflow/tracking/fluent.py", line 135, in set_experiment
[2023-11-22T15:28:26.340+0500] {subprocess.py:93} INFO -     experiment = client.get_experiment_by_name(experiment_name)
[2023-11-22T15:28:26.341+0500] {subprocess.py:93} INFO -   File "/home/makar/.local/lib/python3.10/site-packages/mlflow/tracking/client.py", line 513, in get_experiment_by_name
[2023-11-22T15:28:26.342+0500] {subprocess.py:93} INFO -     return self._tracking_client.get_experiment_by_name(name)
[2023-11-22T15:28:26.343+0500] {subprocess.py:93} INFO -   File "/home/makar/.local/lib/python3.10/site-packages/mlflow/tracking/_tracking_service/client.py", line 221, in get_experiment_by_name
[2023-11-22T15:28:26.344+0500] {subprocess.py:93} INFO -     return self.store.get_experiment_by_name(name)
[2023-11-22T15:28:26.345+0500] {subprocess.py:93} INFO -   File "/home/makar/.local/lib/python3.10/site-packages/mlflow/store/tracking/rest_store.py", line 306, in get_experiment_by_name
[2023-11-22T15:28:26.346+0500] {subprocess.py:93} INFO -     response_proto = self._call_endpoint(GetExperimentByName, req_body)
[2023-11-22T15:28:26.347+0500] {subprocess.py:93} INFO -   File "/home/makar/.local/lib/python3.10/site-packages/mlflow/store/tracking/rest_store.py", line 59, in _call_endpoint
[2023-11-22T15:28:26.348+0500] {subprocess.py:93} INFO -     return call_endpoint(self.get_host_creds(), endpoint, method, json_body, response_proto)
[2023-11-22T15:28:26.349+0500] {subprocess.py:93} INFO -   File "/home/makar/.local/lib/python3.10/site-packages/mlflow/utils/rest_utils.py", line 206, in call_endpoint
[2023-11-22T15:28:26.350+0500] {subprocess.py:93} INFO -     response = http_request(**call_kwargs)
[2023-11-22T15:28:26.351+0500] {subprocess.py:93} INFO -   File "/home/makar/.local/lib/python3.10/site-packages/mlflow/utils/rest_utils.py", line 120, in http_request
[2023-11-22T15:28:26.352+0500] {subprocess.py:93} INFO -     raise MlflowException(f"API request to {url} failed with exception {e}")
[2023-11-22T15:28:26.353+0500] {subprocess.py:93} INFO - mlflow.exceptions.MlflowException: API request to http://localhost:5000/api/2.0/mlflow/experiments/get-by-name failed with exception HTTPConnectionPool(host='localhost', port=5000): Max retries exceeded with url: /api/2.0/mlflow/experiments/get-by-name?experiment_name=get_data (Caused by NewConnectionError('<urllib3.connection.HTTPConnection object at 0x7f9912234940>: Failed to establish a new connection: [Errno 111] Connection refused'))
[2023-11-22T15:28:26.897+0500] {subprocess.py:97} INFO - Command exited with return code 1
[2023-11-22T15:28:26.951+0500] {taskinstance.py:1937} ERROR - Task failed with exception
Traceback (most recent call last):
  File "/usr/local/lib/python3.10/dist-packages/airflow/operators/bash.py", line 210, in execute
    raise AirflowException(
airflow.exceptions.AirflowException: Bash command failed. The command returned a non-zero exit code 1.
[2023-11-22T15:28:26.963+0500] {taskinstance.py:1400} INFO - Marking task as UP_FOR_RETRY. dag_id=competition, task_id=get_data, execution_date=20231121T000000, start_date=20231122T102718, end_date=20231122T102826
[2023-11-22T15:28:27.012+0500] {standard_task_runner.py:104} ERROR - Failed to execute job 49 for task get_data (Bash command failed. The command returned a non-zero exit code 1.; 9994)
[2023-11-22T15:28:27.067+0500] {local_task_job_runner.py:228} INFO - Task exited with return code 1
[2023-11-22T15:28:27.168+0500] {taskinstance.py:2778} INFO - 0 downstream tasks scheduled from follow-on schedule check
