[2023-11-21T16:52:14.849+0500] {taskinstance.py:1159} INFO - Dependencies all met for dep_context=non-requeueable deps ti=<TaskInstance: competition.get_data manual__2023-11-21T11:33:03.730769+00:00 [queued]>
[2023-11-21T16:52:14.885+0500] {taskinstance.py:1159} INFO - Dependencies all met for dep_context=requeueable deps ti=<TaskInstance: competition.get_data manual__2023-11-21T11:33:03.730769+00:00 [queued]>
[2023-11-21T16:52:14.886+0500] {taskinstance.py:1361} INFO - Starting attempt 2 of 2
[2023-11-21T16:52:14.941+0500] {taskinstance.py:1382} INFO - Executing <Task(BashOperator): get_data> on 2023-11-21 11:33:03.730769+00:00
[2023-11-21T16:52:14.958+0500] {standard_task_runner.py:57} INFO - Started process 10726 to run task
[2023-11-21T16:52:14.968+0500] {standard_task_runner.py:84} INFO - Running: ['airflow', 'tasks', 'run', 'competition', 'get_data', 'manual__2023-11-21T11:33:03.730769+00:00', '--job-id', '10', '--raw', '--subdir', 'DAGS_FOLDER/competition_score.py', '--cfg-path', '/tmp/tmpujjpsg5j']
[2023-11-21T16:52:14.974+0500] {standard_task_runner.py:85} INFO - Job 10: Subtask get_data
[2023-11-21T16:52:15.216+0500] {task_command.py:416} INFO - Running <TaskInstance: competition.get_data manual__2023-11-21T11:33:03.730769+00:00 [running]> on host Acer
[2023-11-21T16:52:15.606+0500] {taskinstance.py:1662} INFO - Exporting env vars: AIRFLOW_CTX_DAG_OWNER='makar' AIRFLOW_CTX_DAG_ID='competition' AIRFLOW_CTX_TASK_ID='get_data' AIRFLOW_CTX_EXECUTION_DATE='2023-11-21T11:33:03.730769+00:00' AIRFLOW_CTX_TRY_NUMBER='2' AIRFLOW_CTX_DAG_RUN_ID='manual__2023-11-21T11:33:03.730769+00:00'
[2023-11-21T16:52:15.613+0500] {subprocess.py:63} INFO - Tmp dir root location: /tmp
[2023-11-21T16:52:15.617+0500] {subprocess.py:75} INFO - Running command: ['/usr/bin/bash', '-c', 'python3 /home/makar/MLops_3/scripts/get_data.py']
[2023-11-21T16:52:15.655+0500] {subprocess.py:86} INFO - Output:
[2023-11-21T16:52:26.753+0500] {subprocess.py:93} INFO - Traceback (most recent call last):
[2023-11-21T16:52:26.754+0500] {subprocess.py:93} INFO -   File "/home/makar/MLops_3/scripts/get_data.py", line 18, in <module>
[2023-11-21T16:52:26.755+0500] {subprocess.py:93} INFO -     mlflow.log_artifact(local_path="/home/MLops_3/scripts/get_data.py",
[2023-11-21T16:52:26.756+0500] {subprocess.py:93} INFO -   File "/home/makar/.local/lib/python3.10/site-packages/mlflow/tracking/fluent.py", line 986, in log_artifact
[2023-11-21T16:52:26.757+0500] {subprocess.py:93} INFO -     MlflowClient().log_artifact(run_id, local_path, artifact_path)
[2023-11-21T16:52:26.758+0500] {subprocess.py:93} INFO -   File "/home/makar/.local/lib/python3.10/site-packages/mlflow/tracking/client.py", line 1142, in log_artifact
[2023-11-21T16:52:26.759+0500] {subprocess.py:93} INFO -     self._tracking_client.log_artifact(run_id, local_path, artifact_path)
[2023-11-21T16:52:26.760+0500] {subprocess.py:93} INFO -   File "/home/makar/.local/lib/python3.10/site-packages/mlflow/tracking/_tracking_service/client.py", line 529, in log_artifact
[2023-11-21T16:52:26.762+0500] {subprocess.py:93} INFO -     artifact_repo.log_artifact(local_path, artifact_path)
[2023-11-21T16:52:26.764+0500] {subprocess.py:93} INFO -   File "/home/makar/.local/lib/python3.10/site-packages/mlflow/store/artifact/local_artifact_repo.py", line 38, in log_artifact
[2023-11-21T16:52:26.765+0500] {subprocess.py:93} INFO -     shutil.copy2(local_file, os.path.join(artifact_dir, os.path.basename(local_file)))
[2023-11-21T16:52:26.766+0500] {subprocess.py:93} INFO -   File "/usr/lib/python3.10/shutil.py", line 434, in copy2
[2023-11-21T16:52:26.768+0500] {subprocess.py:93} INFO -     copyfile(src, dst, follow_symlinks=follow_symlinks)
[2023-11-21T16:52:26.769+0500] {subprocess.py:93} INFO -   File "/usr/lib/python3.10/shutil.py", line 254, in copyfile
[2023-11-21T16:52:26.770+0500] {subprocess.py:93} INFO -     with open(src, 'rb') as fsrc:
[2023-11-21T16:52:26.772+0500] {subprocess.py:93} INFO - FileNotFoundError: [Errno 2] No such file or directory: '/home/MLops_3/scripts/get_data.py'
[2023-11-21T16:52:27.407+0500] {subprocess.py:97} INFO - Command exited with return code 1
[2023-11-21T16:52:27.472+0500] {taskinstance.py:1937} ERROR - Task failed with exception
Traceback (most recent call last):
  File "/usr/local/lib/python3.10/dist-packages/airflow/operators/bash.py", line 210, in execute
    raise AirflowException(
airflow.exceptions.AirflowException: Bash command failed. The command returned a non-zero exit code 1.
[2023-11-21T16:52:27.486+0500] {taskinstance.py:1400} INFO - Marking task as FAILED. dag_id=competition, task_id=get_data, execution_date=20231121T113303, start_date=20231121T115214, end_date=20231121T115227
[2023-11-21T16:52:27.536+0500] {standard_task_runner.py:104} ERROR - Failed to execute job 10 for task get_data (Bash command failed. The command returned a non-zero exit code 1.; 10726)
[2023-11-21T16:52:27.582+0500] {local_task_job_runner.py:228} INFO - Task exited with return code 1
[2023-11-21T16:52:27.698+0500] {taskinstance.py:2778} INFO - 0 downstream tasks scheduled from follow-on schedule check
